Workbook
Name _ftn1: 'Normativa Especies'!$C$997
Name _ftn10: 'Normativa Especies'!$C$1020
Name _ftn11: 'Normativa Especies'!$C$1027
Name _ftn12: 'Normativa Especies'!$C$1024
Name _ftn7: 'Normativa Especies'!$C$1006
Name _ftn9: 'Normativa Especies'!$C$1017
Name _ftnref10: 'Normativa Especies'!$C$794
Name _ftnref11: 'Normativa Especies'!$C$919
Name _ftnref12: 'Normativa Especies'!$C$885
Name _ftnref7: 'Normativa Especies'!$C$598
Name _ftnref8: 'Normativa Especies'!$C$417
Name _ftnref9: 'Normativa Especies'!$C$695

Sheet 30TVK15
A1: Grupo | B1: Nombre | C1: Genero | D1: Especie | E1: Infra | F1: CUTM10x10 | G1: EstadoCUTM | H1: FechaCUTM | I1: OrigenCUTM | J1: DescripcionOrigenCUTM | K1: Autor | L1: Reino | M1: Division | N1: Clase | O1: Orden | P1: Familia
A2: Mamíferos | B2: Rattus norvegicus | C2: Rattus | D2: norvegicus | F2: 30TVK15 | G2: Confirmada | H2: 39083 | I2: Atlas y/o Libro Rojo | J2: Atlas y Libro Rojo de los Mamíferos Terrestres de España | K2: (Berkenhout, 1769) | L2: Animalia | M2: Chordata | N2: Mammalia | O2: Roedores | P2: Muridae
A3: Aves | B3: Remiz pendulinus | C3: Remiz | D3: pendulinus | F3: 30TVK15 | G3: Confirmada | H3: 37987 | I3: Atlas y/o Libro Rojo | J3: Libro Rojo de las Aves de España | K3: Linnaeus,1758 | L3: Animalia | M3: Chordata | N3: Aves | O3: Paseriformes | P3: Remizidae
A4: Mamíferos | B4: Apodemus sylvaticus | C4: Apodemus | D4: sylvaticus | F4: 30TVK15 | G4: Confirmada | H4: 39083 | I4: Atlas y/o Libro Rojo | J4: Atlas y Libro Rojo de los Mamíferos Terrestres de España | K4: (Linnaeus, 1758) | L4: Animalia | M4: Chordata | N4: Mammalia | O4: Roedores | P4: Muridae
A5: Peces continentales | B5: Barbus bocagei | C5: Barbus | D5: bocagei | F5: 30TVK15 | G5: Confirmada | H5: 36892 | I5: Atlas y/o Libro Rojo | J5: Atlas y Libro Rojo de los Peces Continentales de España | K5: Steindachner, 1864 | L5: Animalia | M5: Chordata | N5: Actinopterygii | O5: Cypriniformes | P5: Cyprinidae
A6: Mamíferos | B6: Vulpes vulpes | C6: Vulpes | D6: vulpes | F6: 30TVK15 | G6: Confirmada | H6: 39083 | I6: Atlas y/o Libro Rojo | J6: Atlas y Libro Rojo de los Mamíferos Terrestres de España | K6: (Linnaeus, 1758) | L6: Animalia | M6: Chordata | N6: Mammalia | O6: Carnívoros | P6: Canidae
A7: Peces continentales | B7: Cobitis paludica | C7: Cobitis | D7: paludica | F7: 30TVK15 | G7: No Confirmada | H7: 39814 | I7: Seguimiento | J7: Ictiofauna Continental Española, 2011 | K7: De Buen, 1930 | L7: Animalia | M7: Chordata | N7: Actinopterygii | O7: Cypriniformes | P7: Cobitidae
A8: Peces continentales | B8: Cobitis paludica | C8: Cobitis | D8: paludica | F8: 30TVK15 | G8: Confirmada | H8: 36892 | I8: Atlas y/o Libro Rojo | J8: Atlas y Libro Rojo de los Peces Continentales de España | K8: De Buen, 1930 | L8: Animalia | M8: Chordata | N8: Actinopterygii | O8: Cypriniformes | P8: Cobitidae
A9: Mamíferos | B9: Crocidura russula | C9: Crocidura | D9: russula | F9: 30TVK15 | G9: Confirmada | H9: 39083 | I9: Atlas y/o Libro Rojo | J9: Atlas y Libro Rojo de los Mamíferos Terrestres de España | K9: (Hermann, 1780) | L9: Animalia | M9: Chordata | N9: Mammalia | O9: Soricomorfos | P9: Soricidae
A10: Reptiles | B10: Psammodromus algirus | C10: Psammodromus | D10: algirus | F10: 30TVK15 | G10: Confirmada | H10: 37257 | I10: Otros | J10: Base de Datos Herpetológica, 2011 | K10: (Linnaeus, 1758) | L10: Animalia | M10: Chordata | N10: Reptilia | O10: Squamata | P10: Lacertidae
A11: Mamíferos | B11: Mus musculus | C11: Mus | D11: musculus | F11: 30TVK15 | G11: Confirmada | H11: 39083 | I11: Atlas y/o Libro Rojo | J11: Atlas y Libro Rojo de los Mamíferos Terrestres de España | K11: - | L11: Animalia | M11: Chordata | N11: Mammalia | O11: Roedores | P11: Muridae
A12: Aves | B12: Cecropis daurica | C12: Cecropis | D12: daurica | F12: 30TVK15 | G12: Confirmada | H12: 37987 | I12: Atlas y/o Libro Rojo | J12: Libro Rojo de las Aves de España | K12: Linneo,1771 | L12: Animalia | M12: Chordata | N12: Aves | O12: Paseriformes | P12: Hirundinidae
A13: Aves | B13: Circus aeruginosus | C13: Circus | D13: aeruginosus | F13: 30TVK15 | G13: Confirmada | H13: 38718 | I13: Otros | J13: Seguimientos Específicos | K13: Linnaeus,1758 | L13: Animalia | M13: Chordata | N13: Aves | O13: Falconiformes | P13: Accipitridae
... A135: Aves | B135: Oenanthe hispanica | C135: Oenanthe | D135: hispanica | F135: 30TVK15 | G135: Confirmada | H135: 37987 | I135: Atlas y/o Libro Rojo | J135: Libro Rojo de las Aves de España | K135: Linnaeus,1758 | L135: Animalia | M135: Chordata | N135: Aves | O135: Paseriformes | P135: Turdidae

Sheet 🦅 Inventario Fauna
A1: Inventario Faunístico — Proyecto
A2: CATEGORÍAS: | B2: 🟠 En peligro de extinción | C2: 🟡 Vulnerable | D2: 🟢 Otro
A3: Nombre científico | B3: Nombre común | C3: Grupo | D3: LESRPE/CEEA | E3: Cat. Madrid | F3: Normativa autonómica | H3: Cat. España | I3: Cat. amenaza (Listado/Catálogo Madrid)
A4: Rattus norvegicus | B4: — | C4: Mamíferos | D4: — | E4: — | F4: — | H4: =IFERROR(INDEX('Normativa Especies'!$H$2:$H$995,MATCH(TRIM(A4),'Normativa Especies'!$M$2:$M$995,0)),"-") -> - | I4: =IFERROR(INDEX(FAUNA!$D$2:$D$134,MATCH(TRIM(A4),FAUNA!$E$1:E134,0)),"-") -> -
A5: Remiz pendulinus | B5: Pájaro moscón | C5: Aves | D5: LESRPE | E5: — | F5: — | H5: =IFERROR(INDEX('Normativa Especies'!$H$2:$H$995,MATCH(TRIM(A5),'Normativa Especies'!$M$2:$M$995,0)),"-") -> LESRPE | I5: =IFERROR(INDEX(FAUNA!$D$2:$D$134,MATCH(TRIM(A5),FAUNA!$E$1:E135,0)),"-") -> -
A6: Apodemus sylvaticus | B6: — | C6: Mamíferos | D6: — | E6: — | F6: — | H6: =IFERROR(INDEX('Normativa Especies'!$H$2:$H$995,MATCH(TRIM(A6),'Normativa Especies'!$M$2:$M$995,0)),"-") -> - | I6: =IFERROR(INDEX(FAUNA!$D$2:$D$134,MATCH(TRIM(A6),FAUNA!$E$1:E136,0)),"-") -> -
A7: Barbus bocagei | B7: — | C7: Peces continentales | D7: — | E7: — | F7: — | H7: =IFERROR(INDEX('Normativa Especies'!$H$2:$H$995,MATCH(TRIM(A7),'Normativa Especies'!$M$2:$M$995,0)),"-") -> - | I7: =IFERROR(INDEX(FAUNA!$D$2:$D$134,MATCH(TRIM(A7),FAUNA!$E$1:E137,0)),"-") -> -
A8: Vulpes vulpes | B8: — | C8: Mamíferos | D8: — | E8: — | F8: — | H8: =IFERROR(INDEX('Normativa Especies'!$H$2:$H$995,MATCH(TRIM(A8),'Normativa Especies'!$M$2:$M$995,0)),"-") -> - | I8: =IFERROR(INDEX(FAUNA!$D$2:$D$134,MATCH(TRIM(A8),FAUNA!$E$1:E138,0)),"-") -> -
A9: Cobitis paludica | B9: — | C9: Peces continentales | D9: — | E9: — | F9: — | H9: =IFERROR(INDEX('Normativa Especies'!$H$2:$H$995,MATCH(TRIM(A9),'Normativa Especies'!$M$2:$M$995,0)),"-") -> - | I9: =IFERROR(INDEX(FAUNA!$D$2:$D$134,MATCH(TRIM(A9),FAUNA!$E$1:E139,0)),"-") -> -
A10: Crocidura russula | B10: — | C10: Mamíferos | D10: — | E10: — | F10: — | H10: =IFERROR(INDEX('Normativa Especies'!$H$2:$H$995,MATCH(TRIM(A10),'Normativa Especies'!$M$2:$M$995,0)),"-") -> - | I10: =IFERROR(INDEX(FAUNA!$D$2:$D$134,MATCH(TRIM(A10),FAUNA!$E$1:E140,0)),"-") -> -
A11: Psammodromus algirus | B11: Lagartija colilarga | C11: Reptiles | D11: LESRPE | E11: — | F11: — | H11: =IFERROR(INDEX('Normativa Especies'!$H$2:$H$995,MATCH(TRIM(A11),'Normativa Especies'!$M$2:$M$995,0)),"-") -> LESRPE | I11: =IFERROR(INDEX(FAUNA!$D$2:$D$134,MATCH(TRIM(A11),FAUNA!$E$1:E141,0)),"-") -> -
A12: Mus musculus | B12: — | C12: Mamíferos | D12: — | E12: — | F12: — | H12: =IFERROR(INDEX('Normativa Especies'!$H$2:$H$995,MATCH(TRIM(A12),'Normativa Especies'!$M$2:$M$995,0)),"-") -> - | I12: =IFERROR(INDEX(FAUNA!$D$2:$D$134,MATCH(TRIM(A12),FAUNA!$E$1:E142,0)),"-") -> -
A13: Cecropis daurica | B13: Golondrina daúrica | C13: Aves | D13: LESRPE | E13: — | F13: — | H13: =IFERROR(INDEX('Normativa Especies'!$H$2:$H$995,MATCH(TRIM(A13),'Normativa Especies'!$M$2:$M$995,0)),"-") -> - | I13: =IFERROR(INDEX(FAUNA!$D$2:$D$134,MATCH(TRIM(A13),FAUNA!$E$1:E143,0)),"-") -> -
A14: Circus aeruginosus | B14: — | C14: Aves | D14: LESRPE | E14: SENSIBLES | F14: Decreto 18/1992, de 26 de marzo, por el | H14: =IFERROR(INDEX('Normativa Especies'!$H$2:$H$995,MATCH(TRIM(A14),'Normativa Especies'!$M$2:$M$995,0)),"-") -> LESRPE | I14: =IFERROR(INDEX(FAUNA!$D$2:$D$134,MATCH(TRIM(A14),FAUNA!$E$1:E144,0)),"-") -> Sensibles a la alteración de su hábitat
A15: Alytes cisternasii | B15: Sapo partero ibérico | C15: Anfibios | D15: LESRPE | E15: — | F15: — | H15: =IFERROR(INDEX('Normativa Especies'!$H$2:$H$995,MATCH(TRIM(A15),'Normativa Especies'!$M$2:$M$995,0)),"-") -> LESRPE | I15: =IFERROR(INDEX(FAUNA!$D$2:$D$134,MATCH(TRIM(A15),FAUNA!$E$1:E145,0)),"-") -> -
... A132: Oenanthe hispanica | B132: Collalba rubia | C132: Aves | D132: LESRPE | E132: — | F132: — | H132: =IFERROR(INDEX('Normativa Especies'!$H$2:$H$995,MATCH(TRIM(A132),'Normativa Especies'!$M$2:$M$995,0)),"-") -> LESRPE | I132: =IFERROR(INDEX(FAUNA!$D$2:$D$134,MATCH(TRIM(A132),FAUNA!$E$1:E262,0)),"-") -> -
A134: TOTALES POR CATEGORÍA
A135: Categoría | B135: LESRPE/CEEA | C135: Cat. Madrid
A136: 🟠 En peligro de extinción | B136: 1 | C136: 0
A137: 🟡 Vulnerable | B137: 2 | C137: 4
A138: 🟢 Otro | B138: 64 | C138: 12
A140: Nota: 'LESRPE/CEEA' y 'Cat. Madrid' cuentan especies por fuente normativa de forma independiente; una misma especie puede figurar en ambas columnas si tiene protección tanto nacional como autonómica.

Sheet 🌿 Inventario Flora
A1: Inventario Florístico — Planta solar El Álamo
A2: CATEGORÍAS: | B2: 🟠 En peligro de extinción | C2: 🟡 Vulnerable | D2: 🟢 Otro
A3: Nombre científico | B3: Nombre común | C3: Grupo | D3: LESRPE/CEEA | E3: Cat. Madrid | F3: Normativa autonómica | H3: Cat. España | I3: Cat. amenaza (Listado/Catálogo Madrid)
A4: Anagallis tenella | B4: — | C4: Flora | D4: — | E4: — | F4: — | H4: =IFERROR(INDEX('Normativa Especies'!$H$2:$H$995,MATCH(TRIM(A4),'Normativa Especies'!$C$2:$C$995,0)),"-") -> - | I4: =IFERROR(INDEX(FLORA!$C$2:$C$107,MATCH(TRIM(A4),FLORA!$D$1:$D$107,0)),"-") -> -
A5: Anchusa undulata | B5: — | C5: Flora | D5: — | E5: — | F5: — | H5: =IFERROR(INDEX('Normativa Especies'!$H$2:$H$995,MATCH(TRIM(A5),'Normativa Especies'!$C$2:$C$995,0)),"-") -> - | I5: =IFERROR(INDEX(FLORA!$C$2:$C$107,MATCH(TRIM(A5),FLORA!$D$1:$D$107,0)),"-") -> -
A6: Apium inundatum | B6: — | C6: Flora | D6: — | E6: — | F6: — | H6: =IFERROR(INDEX('Normativa Especies'!$H$2:$H$995,MATCH(TRIM(A6),'Normativa Especies'!$C$2:$C$995,0)),"-") -> - | I6: =IFERROR(INDEX(FLORA!$C$2:$C$107,MATCH(TRIM(A6),FLORA!$D$1:$D$107,0)),"-") -> -
A7: Bromus hordeaceus | B7: — | C7: Flora | D7: — | E7: — | F7: — | H7: =IFERROR(INDEX('Normativa Especies'!$H$2:$H$995,MATCH(TRIM(A7),'Normativa Especies'!$C$2:$C$995,0)),"-") -> - | I7: =IFERROR(INDEX(FLORA!$C$2:$C$107,MATCH(TRIM(A7),FLORA!$D$1:$D$107,0)),"-") -> -
A8: Bromus rubens | B8: — | C8: Flora | D8: — | E8: — | F8: — | H8: =IFERROR(INDEX('Normativa Especies'!$H$2:$H$995,MATCH(TRIM(A8),'Normativa Especies'!$C$2:$C$995,0)),"-") -> - | I8: =IFERROR(INDEX(FLORA!$C$2:$C$107,MATCH(TRIM(A8),FLORA!$D$1:$D$107,0)),"-") -> -
A9: Bromus tectorum | B9: — | C9: Flora | D9: — | E9: — | F9: — | H9: =IFERROR(INDEX('Normativa Especies'!$H$2:$H$995,MATCH(TRIM(A9),'Normativa Especies'!$C$2:$C$995,0)),"-") -> - | I9: =IFERROR(INDEX(FLORA!$C$2:$C$107,MATCH(TRIM(A9),FLORA!$D$1:$D$107,0)),"-") -> -
A10: Coincya monensis subsp. orophila | B10: — | C10: Flora | D10: — | E10: — | F10: — | H10: =IFERROR(INDEX('Normativa Especies'!$H$2:$H$995,MATCH(TRIM(A10),'Normativa Especies'!$C$2:$C$995,0)),"-") -> - | I10: =IFERROR(INDEX(FLORA!$C$2:$C$107,MATCH(TRIM(A10),FLORA!$D$1:$D$107,0)),"-") -> -
A11: Euphorbia matritensis | B11: — | C11: Flora | D11: — | E11: — | F11: — | H11: =IFERROR(INDEX('Normativa Especies'!$H$2:$H$995,MATCH(TRIM(A11),'Normativa Especies'!$C$2:$C$995,0)),"-") -> - | I11: =IFERROR(INDEX(FLORA!$C$2:$C$107,MATCH(TRIM(A11),FLORA!$D$1:$D$107,0)),"-") -> -
A12: Gnaphalium uliginosum | B12: — | C12: Flora | D12: — | E12: — | F12: — | H12: =IFERROR(INDEX('Normativa Especies'!$H$2:$H$995,MATCH(TRIM(A12),'Normativa Especies'!$C$2:$C$995,0)),"-") -> - | I12: =IFERROR(INDEX(FLORA!$C$2:$C$107,MATCH(TRIM(A12),FLORA!$D$1:$D$107,0)),"-") -> -
A13: Hypericum australe | B13: — | C13: Flora | D13: — | E13: — | F13: — | H13: =IFERROR(INDEX('Normativa Especies'!$H$2:$H$995,MATCH(TRIM(A13),'Normativa Especies'!$C$2:$C$995,0)),"-") -> - | I13: =IFERROR(INDEX(FLORA!$C$2:$C$107,MATCH(TRIM(A13),FLORA!$D$1:$D$107,0)),"-") -> -
A14: Isolepis pseudosetacea | B14: — | C14: Flora | D14: — | E14: — | F14: — | H14: =IFERROR(INDEX('Normativa Especies'!$H$2:$H$995,MATCH(TRIM(A14),'Normativa Especies'!$C$2:$C$995,0)),"-") -> - | I14: =IFERROR(INDEX(FLORA!$C$2:$C$107,MATCH(TRIM(A14),FLORA!$D$1:$D$107,0)),"-") -> -
A15: Juncus articulatus | B15: — | C15: Flora | D15: — | E15: — | F15: — | H15: =IFERROR(INDEX('Normativa Especies'!$H$2:$H$995,MATCH(TRIM(A15),'Normativa Especies'!$C$2:$C$995,0)),"-") -> - | I15: =IFERROR(INDEX(FLORA!$C$2:$C$107,MATCH(TRIM(A15),FLORA!$D$1:$D$107,0)),"-") -> -
... A31: Veronica anagallis-aquatica subsp. anagallis-aquatica | B31: — | C31: Flora | D31: — | E31: — | F31: — | H31: =IFERROR(INDEX('Normativa Especies'!$H$2:$H$995,MATCH(TRIM(A31),'Normativa Especies'!$C$2:$C$995,0)),"-") -> - | I31: =IFERROR(INDEX(FLORA!$C$2:$C$107,MATCH(TRIM(A31),FLORA!$D$1:$D$107,0)),"-") -> -
A33: TOTALES POR CATEGORÍA
A34: Categoría | B34: LESRPE/CEEA | C34: Cat. Madrid
A36: Nota: 'LESRPE/CEEA' y 'Cat. Madrid' cuentan especies por fuente normativa de forma independiente; una misma especie puede figurar en ambas columnas si tiene protección tanto nacional como autonómica.

Sheet FAUNA
A1: Orden / Grupo | B1: Nombre común | C1: Nombre científico | D1: Categoria de amenaza | E1: Nombre científico
A2: Orthoptera | C2: Saga pedo (Tettigonidae) Palles | D2: En peligro de extinción | E2: Saga pedo
A3: Orthoptera | C3: Podisma carpetana (Catantopidae) Bolivar | D3: En peligro de extinción | E3: Podisma carpetana
A4: Lepidoptera | C4: Parnassius apollo (Papilionidae) Linnaeus | D4: En peligro de extinción | E4: Parnassius apollo
A5: Dyctyoptera | C5: Apteromantis aptera De la Fuente | D5: En peligro de extinción | E5: Apteromantis aptera
A6: Ephemeroptera | C6: Serratella hispanica (Ephemerelledae) Eaton | D6: Sensibles a la alteración de su hábitat | E6: Serratella hispanica
A7: Ephemeroptera | C7: Drunella paradinasi (Ephemerellidae) Tánago y Jalón | D7: Sensibles a la alteración de su hábitat | E7: Drunella paradinasi
A8: Odonata | C8: Cocnagrion mercuriale (Caenogriidae) Charpentier | D8: Sensibles a la alteración de su hábitat | E8: Cocnagrion mercuriale
A9: Orthoptera | C9: Steropleurus obsoletus (Tettigonidae) Bolivar | D9: Sensibles a la alteración de su hábitat | E9: Steropleurus obsoletus
A10: Orthoptera | C10: Dociostaurus crassiusculus (Acrididae) Pantel | D10: Sensibles a la alteración de su hábitat | E10: Dociostaurus crassiusculus
A11: Orthoptera | C11: Dociostaurus hispanicos (Acrididae) Bolivar | D11: Sensibles a la alteración de su hábitat | E11: Dociostaurus hispanicos
A12: Orthoptera | C12: Arcyptera tornosi (Acrididae) Bolivar | D12: Sensibles a la alteración de su hábitat | E12: Arcyptera tornosi
A13: Orthoptera | C13: Sciobia lusitanica (Gryllidae) Rambur | D13: Sensibles a la alteración de su hábitat | E13: Sciobia lusitanica
... A43: Lepidoptera | C43: Ocnogyna zoraida (Arctiidae) Graslin | D43: De interés especial | E43: Ocnogyna zoraida
A44: Peces | B44: Calandino | C44: Tropidophoxinellus alburnoides Steindachner | D44: En peligro de extinción | E44: Tropidophoxinellus alburnoides
A45: Peces | B45: Anguila | C45: Anguilla anguilla Linnaeus | D45: En peligro de extinción | E45: Anguilla anguilla
A46: Peces | B46: Colmilleja o Lamprehuela | C46: Cobitis calderoni Steindachner | D46: En peligro de extinción | E46: Cobitis calderoni
A47: Peces | B47: Barbo comiza | C47: Barbus comiza Bacescu | D47: En peligro de extinción | E47: Barbus comiza
A48: Anfibios | B48: Tritón alpino | C48: Triturus alpestris Wolterstorff | D48: En peligro de extinción | E48: Triturus alpestris
A49: Reptiles | B49: Galápago europeo | C49: Emys orbicularis Linnaeus | D49: En peligro de extinción | E49: Emys orbicularis
A50: Aves | B50: Alimoche | C50: Neophron percnopterus Linnaeus | D50: En peligro de extinción | E50: Neophron percnopterus
A51: Aves | B51: Águila Perdicera | C51: Hieraaetus fasciatus Vieillot | D51: En peligro de extinción | E51: Hieraaetus fasciatus
A52: Aves | B52: Águila Imperial ibérica | C52: Aquila adalberti C.L. Brehm | D52: En peligro de extinción | E52: Aquila adalberti
A53: Aves | B53: Cigüeña negra | C53: Ciconia nigra Linnaeus | D53: En peligro de extinción | E53: Ciconia nigra
A54: Aves | B54: Buitre negro | C54: Aegypius monachus Linnaeus | D54: En peligro de extinción | E54: Aegypius monachus
A55: Aves | B55: Cernícalo primilla | C55: Falco naumanni Fleischer | D55: En peligro de extinción | E55: Falco naumanni
... A134: Reptiles | B134: Lagarto verdinegro | C134: Lacerta schreiberi Bedriaga | D134: De interés especial | E134: Lacerta schreiberi

Sheet FLORA
A1: Nombre común | B1: Nombre científico | C1: Categoria de amenaza | D1: Nombre científico
B2: Hohenackeria polyodon Cosson et Durieu | C2: En peligro de extinción | D2: Hohenackeria polyodon
B3: Lycopodiella inundata C. Börner | C3: En peligro de extinción | D3: Lycopodiella inundata
B4: Narcissus pseudonarcissus confusus Linnaeus | C4: En peligro de extinción | D4: Narcissus pseudonarcissus confusus
B5: Polystichum lonchitis Roth | C5: En peligro de extinción | D5: Polystichum lonchitis
A6: Sapina | B6: Arthrocnemum machrostachyum (Delile) Ung.-Stern | C6: Sensibles a la alteración de su hábitat | D6: Arthrocnemum machrostachyum
A7: Jaguarzo amarillo | B7: Halimium commutatum Pau | C7: Sensibles a la alteración de su hábitat | D7: Halimium commutatum
A8: Toronjil silvestre | B8: Melittis melissophyllum Linnaeus | C8: Sensibles a la alteración de su hábitat | D8: Melittis melissophyllum
A9: Nébeda del Beltrán | B9: Nepeta beltranii Pau | C9: Sensibles a la alteración de su hábitat | D9: Nepeta beltranii
A10: Peralillo, piruétano | B10: Pyrus bourgaeana Decne | C10: Sensibles a la alteración de su hábitat | D10: Pyrus bourgaeana
A11: Jaramugo de Cavanilles | B11: Sisymbrium cavanillesianum Castrov. et Val. Berm. | C11: Sensibles a la alteración de su hábitat | D11: Sisymbrium cavanillesianum
A12: Acebo | B12: Ilex aquifolium Linnaeus | C12: Sensibles a la alteración de su hábitat | D12: Ilex aquifolium
A13: Sabina albar | B13: Juniperus thurifera Linnaeus | C13: Sensibles a la alteración de su hábitat | D13: Juniperus thurifera
A14: Tejo | B14: Taxus baccata Linnaeus | C14: Sensibles a la alteración de su hábitat | D14: Taxus baccata
A15: Olmo de montaña | B15: Ulmus glabra Hudson | C15: Sensibles a la alteración de su hábitat | D15: Ulmus glabra
A16: Fresno común | B16: Fraxinus excelsior Linnaeus | C16: Sensibles a la alteración de su hábitat | D16: Fraxinus excelsior
A17: Azucena silvestre | B17: Lilium martagon Linnaeus | C17: Sensibles a la alteración de su hábitat | D17: Lilium martagon
... A19: Serbal | B19: Sorbus torminalis (Linnaeus) Crantz. | C19: Sensibles a la alteración de su hábitat | D19: Sorbus torminalis
B20: Nitella flexilis (Linnaeus) Agardh. | C20: Sensibles a la alteración de su hábitat | D20: Nitella flexilis
B21: Nitella mucronata (A. Braun) Miquel | C21: Sensibles a la alteración de su hábitat | D21: Nitella mucronata
B22: Nitella translucens (Pers.) Agardh. | C22: Sensibles a la alteración de su hábitat | D22: Nitella translucens
B23: Riccia fluitans L. Emend. Lorbeer | C23: Sensibles a la alteración de su hábitat | D23: Riccia fluitans
B24: Isoetes histrix Bory | C24: Sensibles a la alteración de su hábitat | D24: Isoetes histrix
B25: Potamogeton perfoliatus Linnaeus | C25: Sensibles a la alteración de su hábitat | D25: Potamogeton perfoliatus
B26: Utricularia minor Linnaeus | C26: Sensibles a la alteración de su hábitat | D26: Utricularia minor
B27: Carex furva Webb | C27: Sensibles a la alteración de su hábitat | D27: Carex furva
B28: Carex umbrosa huetiana Host | C28: Sensibles a la alteración de su hábitat | D28: Carex umbrosa huetiana
B29: Clypeola eriocarpa Cav. | C29: Sensibles a la alteración de su hábitat | D29: Clypeola eriocarpa
B30: Eriophorum latifolium Hoppe | C30: Sensibles a la alteración de su hábitat | D30: Eriophorum latifolium
B31: Hyacinthoides non-scripta (L.) Chov. et Rothm. | C31: Sensibles a la alteración de su hábitat | D31: Hyacinthoides non-scripta
... B33: Juncus alpinoarticulatus auct non Chaix. | C33: Sensibles a la alteración de su hábitat | D33: Juncus alpinoarticulatus
A34: Guillomo | B34: Amelanchier ovalis Medicus | C34: Vulnerables | D34: Amelanchier ovalis
A35: Geranio de El Paular | B35: Erodium paularense Fdez. Gzlez. et Izco | C35: Vulnerables | D35: Erodium paularense
B36: Azolla caroliniana Willd | C36: Vulnerables | D36: Azolla caroliniana
B37: Callitriche truncata truncata Guss | C37: Vulnerables | D37: Callitriche truncata truncata
B38: Juncus bulbosus Linnaeus | C38: Vulnerables | D38: Juncus bulbosus
B39: Litorella uniflora (L.) Ascherson | C39: Vulnerables | D39: Litorella uniflora
B40: Ludwigia palustris (L.) Elliot | C40: Vulnerables | D40: Ludwigia palustris
B41: Menyanthes trifoliata Linnaeus | C41: Vulnerables | D41: Menyanthes trifoliata
B42: Potamogeton gramineus Linnaeus | C42: Vulnerables | D42: Potamogeton gramineus
...

Sheet Normativa Especies
A1: Grupo Taxonómico | B1: TaxonID | C1: Nombre científico LESRPE / CEEA | D1: Nombre científico actualizado | E1: Rango taxonómico | F1: Nombre común | G1: Población referida | H1: Listado de Especies Silvestres en Régimen de Protección Especial (LESRPE)/ Categorías en el Catálogo Español de Especies Amenazadas (CEEA) | I1: Norma | J1: Situación anterior LESRPE / CEEA (en Normativa) | K1: Observaciones
A2: Anfibios | B2: 10909 | C2: Alytes cisternasii | D2: Alytes cisternasii Boscá, 1879 | E2: especie | F2: Sapo partero ibérico | H2: LESRPE | I2: Real Decreto 139/2011 | M2: =TRIM(C2) -> Alytes cisternasii
A3: Anfibios | B3: 11158 | C3: Alytes dickhilleni | D3: Alytes dickhilleni Arntzen & García-París, 1995 | E3: especie | F3: Sapo partero bético | H3: Vulnerable | I3: Real Decreto 139/2011 | M3: =TRIM(C3) -> Alytes dickhilleni
A4: Anfibios | B4: 11790 | C4: Alytes muletensis | D4: Alytes muletensis (Sanchiz & Adrover, 1977) | E4: especie | F4: Ferreret | H4: En peligro de extinción | I4: Real Decreto 139/2011 | M4: =TRIM(C4) -> Alytes muletensis
A5: Anfibios | B5: 11878 | C5: Alytes obstetricans | D5: Alytes obstetricans (Laurenti, 1768) | E5: especie | F5: Sapo partero común | H5: LESRPE | I5: Real Decreto 139/2011 | M5: =TRIM(C5) -> Alytes obstetricans
A6: Anfibios | B6: 16220 | C6: Bufo balearicus (= Bufo viridis) | D6: Bufotes viridis balearicus (Boettger, 1880) | E6: especie | F6: Sapo verde balear | H6: LESRPE | I6: Real Decreto 139/2011 | M6: =TRIM(C6) -> Bufo balearicus (= Bufo viridis)
A7: Anfibios | B7: 10762 | C7: Calotriton arnoldi | D7: Calotriton arnoldi Carranza & Amat, 2005 | E7: especie | F7: Tritón del Montseny | H7: En peligro de extinción | I7: Real Decreto 139/2011 | M7: =TRIM(C7) -> Calotriton arnoldi
A8: Anfibios | B8: 10769 | C8: Calotriton (Euproctus) asper | D8: Calotriton asper (Dugès, 1852) | E8: especie | F8: Tritón pirenaico | H8: LESRPE | I8: Real Decreto 139/2011 | M8: =TRIM(C8) -> Calotriton (Euproctus) asper
A9: Anfibios | B9: 11632 | C9: Chioglossa lusitanica | D9: Chioglossa lusitanica Bocage, 1864 | E9: especie | F9: Salamandra rabilarga | H9: Vulnerable | I9: Real Decreto 139/2011 | M9: =TRIM(C9) -> Chioglossa lusitanica
A10: Anfibios | B10: 11332 | C10: Discoglossus galganoi | D10: Discoglossus galganoi Capula, Nascetti, Lanza, Crespo & Bullini 1985 | E10: especie | F10: Sapillo pintojo ibérico | H10: LESRPE | I10: Real Decreto 139/2011 | M10: =TRIM(C10) -> Discoglossus galganoi
A11: Anfibios | B11: 24211 | C11: Discoglossus jeanneae | D11: Discoglossus galganoi jeanneae Busack, 1986 | E11: subespecie | F11: Sapillo pintojo meridional | H11: LESRPE | I11: Real Decreto 139/2011 | M11: =TRIM(C11) -> Discoglossus jeanneae
A12: Anfibios | B12: 11985 | C12: Discoglossus pictus | D12: Discoglossus pictus (Otth, 1837) | E12: especie | F12: Sapillo pintojo mediterráneo | H12: LESRPE | I12: Real Decreto 139/2011 | M12: =TRIM(C12) -> Discoglossus pictus
A13: Anfibios | B13: 24327 | C13: Bufo calamita | D13: Epidalea calamita (Laurenti, 1768) | E13: especie | F13: Sapo corredor | H13: LESRPE | I13: Real Decreto 139/2011 | M13: =TRIM(C13) -> Bufo calamita
A14: Anfibios | B14: 11717 | C14: Hyla meridionalis | D14: Hyla meridionalis Boettger, 1874 | E14: especie | F14: Ranita meridional | G14: Península y Baleares | H14: LESRPE | I14: Real Decreto 139/2011 | M14: =TRIM(C14) -> Hyla meridionalis
A15: Anfibios | B15: 16222 | C15: Hyla arborea | D15: Hyla molleri (Bedriaga, 1889) | E15: especie | F15: Ranita de San Antón | H15: LESRPE | I15: Real Decreto 139/2011 | M15: =TRIM(C15) -> Hyla arborea
A16: Anfibios | B16: 10729 | C16: Lissotriton boscai (antes Triturus boscai) | D16: Lissotriton boscai (Lataste, 1879) | E16: especie | F16: Tritón ibérico | H16: LESRPE | I16: Real Decreto 139/2011 | M16: =TRIM(C16) -> Lissotriton boscai (antes Triturus boscai)
A17: Anfibios | B17: 11431 | C17: Lissotriton helveticus (antes Triturus helveticus) | D17: Lissotriton helveticus (Razoumowsky, 1789) | E17: especie | F17: Tritón palmeado | H17: LESRPE | I17: Real Decreto 139/2011 | M17: =TRIM(C17) -> Lissotriton helveticus (antes Triturus helveticus)
A18: Anfibios | B18: 33080 | C18: Mesotriton alpestris (antes Triturus alpestris) | D18: Ichthyosaura alpestris (Laurenti, 1768) | E18: especie | F18: Tritón alpino | H18: Vulnerable | I18: Real Decreto 139/2011 | M18: =TRIM(C18) -> Mesotriton alpestris (antes Triturus alpestris)
A19: Anfibios | B19: 11108 | C19: Pelobates cultripes | D19: Pelobates cultripes (Cuvier, 1829) | E19: especie | F19: Sapo de espuelas | H19: LESRPE | I19: Real Decreto 139/2011 | M19: =TRIM(C19) -> Pelobates cultripes
A20: Anfibios | B20: 11490 | C20: Pelodytes ibericus (antes P. punctatus) | D20: Pelodytes ibericus Sánchez-Herráiz, Barbadillo, Machordom & Sanchiz, 2000 | E20: especie | F20: Sapillo moteado ibérico | H20: LESRPE | I20: Real Decreto 139/2011 | M20: =TRIM(C20) -> Pelodytes ibericus (antes P. punctatus)
A21: Anfibios | B21: 12037 | C21: Pelodytes punctatus | D21: Pelodytes punctatus (Daudin, 1802) | E21: especie | F21: Sapillo moteado común | H21: LESRPE | I21: Real Decreto 139/2011 | M21: =TRIM(C21) -> Pelodytes punctatus
A22: Anfibios | B22: 12420 | C22: Pleurodeles waltl | D22: Pleurodeles waltl Michahelles, 1830 | E22: especie | F22: Gallipato | H22: LESRPE | I22: Real Decreto 139/2011 | M22: =TRIM(C22) -> Pleurodeles waltl
A23: Anfibios | B23: 11128 | C23: Rana dalmatina | D23: Rana dalmatina Bonaparte, 1840 | E23: especie | F23: Rana ágil | H23: Vulnerable | I23: Real Decreto 139/2011 | M23: =TRIM(C23) -> Rana dalmatina
A24: Anfibios | B24: 11485 | C24: Rana iberica | D24: Rana iberica Boulenger, 1879 | E24: especie | F24: Rana patilarga | H24: LESRPE | I24: Real Decreto 139/2011 | M24: =TRIM(C24) -> Rana iberica
A25: Anfibios | B25: 12056 | C25: Rana pyrenaica | D25: Rana pyrenaica Serra-Cobo, 1993 | E25: especie | F25: Rana pirenaica | H25: Vulnerable | I25: Real Decreto 139/2011 | M25: =TRIM(C25) -> Rana pyrenaica
A26: Anfibios | B26: 12298 | C26: Rana temporaria | D26: Rana temporaria Linnaeus, 1758 | E26: especie | F26: Rana bermeja | H26: LESRPE | I26: Real Decreto 139/2011 | M26: =TRIM(C26) -> Rana temporaria
... A73: Aves | B73: 14010 | C73: Bulweria bulwerii | D73: Bulweria bulwerii (Jardine & Selby, 1828) | E73: especie | F73: Petrel de Bulwer | H73: LESRPE | I73: Real Decreto 139/2011 | M73: =TRIM(C73) -> Bulweria bulwerii
A74: Aves | B74: 11889 | C74: Burhinus oedicnemus distinctus | D74: Burhinus oedicnemus distinctus (Bannerman, 1914) | E74: subespecie | F74: Alcaraván común canario | G74: Canarias Centrales y Occidentales | H74: Vulnerable | I74: Real Decreto 139/2011 | M74: =TRIM(C74) -> Burhinus oedicnemus distinctus
A75: Aves | B75: 11888 | C75: Burhinus oedicnemus oedicnemus/insularum | D75: Burhinus oedicnemus insularum (Sassi, 1908) | E75: subespecie | F75: Alcaraván majorero | G75: Canarias Orientales | H75: LESRPE | I75: Real Decreto 139/2011 | K75: Nombre científico actualizado: Burhinus oedicnemus insularum (Sassi, 1908) Nombre común actualizado: Alcaraván majorero Población referida actualizada: Canarias Orientales | M75: =TRIM(C75) -> Burhinus oedicnemus oedicnemus/insularum
A76: Aves | B76: 28443 | C76: Burhinus oedicnemus oedicnemus/insularum | D76: Burhinus oedicnemus oedicnemus (Linnaeus, 1758) | E76: subespecie | F76: Alcaraván común | G76: Península y Baleares | H76: LESRPE | I76: Real Decreto 139/2011 | K76: Nombre científico actualizado: Burhinus oedicnemus oedicnemus (Linnaeus, 1758) Nombre común actualizado: Alcaraván común Población referida actualizada: Península y Baleares | M76: =TRIM(C76) -> Burhinus oedicnemus oedicnemus/insularum
A77: Aves | B77: 10922 | C77: Buteo buteo | D77: Buteo buteo (Linnaeus, 1758) | E77: especie | F77: Ratonero común | H77: LESRPE | I77: Real Decreto 139/2011 | M77: =TRIM(C77) -> Buteo buteo
A78: Aves | B78: 10734 | C78: Calandrella brachydactyla | D78: Calandrella brachydactyla (Leisler, 1814) | E78: especie | F78: Terrera común | H78: LESRPE | I78: Real Decreto 139/2011 | M78: =TRIM(C78) -> Calandrella brachydactyla
A79: Aves | B79: 33007 | C79: Calandrella rufescens | D79: Alaudala rufescens (Vieillot, 1819) | E79: especie | F79: Terrera marismeña | H79: LESRPE | I79: Real Decreto 139/2011 | M79: =TRIM(C79) -> Calandrella rufescens
A80: Aves | B80: 10649 | C80: Calidris alba | D80: Calidris alba (Pallas, 1764) | E80: especie | F80: Correlimos tridáctilo | H80: LESRPE | I80: Real Decreto 139/2011 | M80: =TRIM(C80) -> Calidris alba
A81: Aves | B81: 10678 | C81: Calidris alpina | D81: Calidris alpina (Linnaeus, 1758) | E81: especie | F81: Correlimos común | H81: LESRPE | I81: Real Decreto 139/2011 | M81: =TRIM(C81) -> Calidris alpina
A82: Aves | B82: 10957 | C82: Calidris canutus | D82: Calidris canutus (Linnaeus, 1758) | E82: especie | F82: Correlimos gordo | H82: LESRPE | I82: Real Decreto 139/2011 | M82: =TRIM(C82) -> Calidris canutus
A83: Aves | B83: 11262 | C83: Calidris ferruginea | D83: Calidris ferruginea (Pontoppidan, 1763) | E83: especie | F83: Correlimos zarapitín | H83: LESRPE | I83: Real Decreto 139/2011 | M83: =TRIM(C83) -> Calidris ferruginea
A84: Aves | B84: 16339 | C84: Calidris maritima | D84: Calidris maritima (Brünnich, 1764) | E84: especie | F84: Correlimos oscuro | H84: LESRPE | I84: Real Decreto 139/2011 | M84: =TRIM(C84) -> Calidris maritima
A85: Aves | B85: 11745 | C85: Calidris minuta | D85: Calidris minuta (Leisler, 1812) | E85: especie | F85: Correlimos menudo | H85: LESRPE | I85: Real Decreto 139/2011 | M85: =TRIM(C85) -> Calidris minuta
A86: Aves | B86: 32348 | C86: Calonectris diomedea borealis | D86: Calonectris borealis (Cory, 1881) | E86: especie | F86: Pardela cenicienta atlántica | H86: LESRPE | I86: Orden TEC/596/2019 | J86: LESRPE como Calonectris diomedea borealis (Real Decreto 139/2011) | K86: En Real Decreto 139/2011 como Calonectris diomedea borealis: Nombre común anterior: Pardela cenicienta Población referida anterior: Atlántico | M86: =TRIM(C86) -> Calonectris diomedea borealis
...
